<?xml version="1.0"?>
<robot name="drag_test">

 <link name="sphere">
 	

 	 <inertial>
            <origin xyz="0 0 0" rpy="1.57 1.57 0"/>
            <mass value="1.5" />
            <inertia ixx="0.00931278333333" ixy="0.0" ixz="0.0" iyy="0.00931278333333" iyz="0.0" izz="0.0070389"/>
        </inertial>

 	<collision>
 		<origin xyz ="0 0 0" rpy="1.57 1.57 0"/>
 		<geometry>
 			<!--<box size="0.09 0.2 0.13"/>-->
      <cylinder radius="0.064" length="0.2"/>
 		</geometry>
 	</collision> 

 	<visual>
 		<origin xyz ="0 0 0" rpy="1.57 1.57 0"/>
 		<geometry>
 			<!--<box size="0.09 0.2 0.13"/>-->
      <cylinder radius="0.064" length="0.2"/>
 		</geometry>
 	</visual> 
 </link>

 <gazebo reference="sphere">
 	<kp>1000000.0</kp>
 	<kd>1000000.0</kd>
 	<mu1>10</mu1>
 	<mu2>10</mu2>
 </gazebo>

<!--
 <link name="fin">
  

   <inertial>
            <origin xyz="-0.09 0 0" rpy="1.57 0 0"/>
            <mass value="0.7383" />
            <inertia ixx="0.00931278333333" ixy="0.0" ixz="0.0" iyy="0.00931278333333" iyz="0.0" izz="0.0070389"/>
        </inertial>

  <collision>
    <origin xyz ="-0.09 0 0" rpy="1.57 0 0"/>
    <geometry>
      <box size="0.09 0.03 0.09"/>
      
    </geometry>
  </collision> 

  <visual>
    <origin xyz ="-0.09 0 0" rpy="1.57 0 0"/>
    <geometry>
      <box size="0.09 0.02 0.09"/>
      
    </geometry>
  </visual> 
 </link>


 <joint name="s_f" type="fixed">
      <parent link="sphere"/>
      <child link="fin"/>
        <origin xyz="0 0 0" rpy="0 0 0"/>
        
        <axis xyz="0 0 1"/>
  </joint>


<link name="fin2">
  

   <inertial>
            <origin xyz="0.09 0 0" rpy="1.57 0 0"/>
            <mass value="0.7383" />
            <inertia ixx="0.00931278333333" ixy="0.0" ixz="0.0" iyy="0.00931278333333" iyz="0.0" izz="0.0070389"/>
        </inertial>

  <collision>
    <origin xyz ="0.09 0 0" rpy="1.57 0 0"/>
    <geometry>
      <box size="0.09 0.02 0.09"/>
      
    </geometry>
  </collision> 

  <visual>
    <origin xyz ="0.09 0 0" rpy="1.57 0 0"/>
    <geometry>
      <box size="0.09 0.02 0.09"/>
      
    </geometry>
  </visual> 
 </link>


 <joint name="s_f2" type="fixed">
      <parent link="sphere"/>
      <child link="fin2"/>
        <origin xyz="0 0 0" rpy="0 0 0"/>
        
        <axis xyz="0 0 1"/>
  </joint>

-->



<link name="cylinder">
 	

 	<inertial>
            <origin xyz="0 0 0" rpy="0 1.57 0"/>
            <mass value="0.743" />
            <inertia ixx="0.0011134" ixy="0.0" ixz="0.0" iyy="0.001256" iyz="0.0" izz="0.0011134"/>
        </inertial>

 	<collision>
 		<origin xyz ="0 0.19 0" rpy="0 1.57 0"/>
 		<geometry>
 			<cylinder radius="0.07" length="0.01"/>
 		</geometry>
 	</collision> 

 	<visual>
 		<origin xyz ="0 0.19 0" rpy="0 1.57 0"/>
 		<geometry> 
 			<cylinder radius="0.07" length="0.01"/>
 		</geometry>
 	</visual> 
 </link>

<gazebo reference="cylinder">
 	<kp>1000000.0</kp>
 	<kd>1000000.0</kd>
 	<mu1>10</mu1>
 	<mu2>10</mu2>
</gazebo>

   <joint name="s_c" type="revolute">
      <parent link="sphere"/>
      <child link="cylinder"/>
        <origin xyz="0 0 0" rpy="0 0 0"/>
        <limit lower="-0.6" upper="0.6" effort="15.0" velocity="20.0"/>
        <axis xyz="0 0 1"/>
  </joint>

<gazebo>
   <plugin name="drag" filename="libdrag.so">
        <fluid_density>1000</fluid_density>
        <fluid_level>3.0</fluid_level>
        <linear_drag>10.0</linear_drag>
        <angular_drag>4.0</angular_drag>
        
          
      </plugin>
  </gazebo>

<gazebo>
  <plugin name="gazebo_ros_control" filename="libgazebo_ros_control.so">
  <robotNamespace>/rrbot</robotNamespace>
  </plugin>
 </gazebo>


  <transmission name="tran1">
    <type>transmission_interface/SimpleTransmission</type>
    <joint name="s_c">
      <hardwareInterface>hardware_interface/EffortJointInterface</hardwareInterface>
    </joint>
    <actuator name="s_c">
      <hardwareInterface>hardware_interface/EffortJointInterface</hardwareInterface>
      <mechanicalReduction>1</mechanicalReduction>
    </actuator>
  </transmission>

  <gazebo>
    <plugin name="s_cfin" filename="libLiftDragPlugin.so">
      <air_density>1000</air_density><cla>0</cla><cla_stall>0</cla_stall><cda>1.254</cda><cda_stall>1.43</cda_stall><alpha_stall>0</alpha_stall><a0>0</a0>
      <area>0.00334</area>   
      <upward>0 0 1.0</upward>
      <forward>1.0 0 0</forward>
      <link_name>cylinder</link_name>
      <cp>0 0 0.019</cp>
    </plugin>
  </gazebo>


</robot>

